Workbook

Sheet Avail List
A1: ECO-FARMS BRISBANE AVAILABILITY LIST
A2: MONDAY 24TH TO WEDNESDAY 26TH AUGUST 2026 | K2: .
A3: CONTACT NAME : | I3: PLEASE CONTACT OUR SALES TEAM IF YOU HAVE QUESTIONS OR NEED ADVICE ON PRODUCE IN STOCK. | K3: .
K4: .
A5: CONTACT NUMBER : | I5: KATELYN | J5: 0420 795 339 | K5: .
I6: ELLA | J6: 0425 330 662 | K6: .
A7: PLEASE TICK OR TYPE "YES" IN THIS BOX IF YOU WOULD LIKE A CALL/TEXT TO NOTIFY YOU OF ANY SHORTAGES. OUR TEAM WILL CALL/TEXT YOU ON THE NUMBER YOU PROVIDE ABOVE EARLY MORNING BEFORE YOUR ORDER LEAVES. THIS WILL GIVE YOU A CHANCE TO ADD A SIMILAR LINE IF THE ONE ORDERED IS UNAVAILABLE. | I7: OFFICE | J7: 07 3892 2400 | K7: .
K8: .
A9: CLICK HERE TO ORDER ONLINE | K9: .
E10: FRESH SPECIALS | K10: .
A11: PRODUCT | B11: SIZE | D11: GROWER | E11: CODE | F11: CUSTOMER COMMENT OR REQUEST | G11: ORDER QTY | H11: PICK QTY | I11: PRICE | J11: Multi Buy Price or Product Info | K11: .
A12: CAPSICUM GREEN | B12: BX | C12: 5KG | D12: ISIS RIVER | E12: CAPBLA | I12: 39 | J12: **SPECIAL** | K12: =G12*I12 -> 0
A13: CARROT PURPLE | B13: BX | C13: 5KG | D13: BIOFARMS | E13: CARPBEN | I13: 24 | J13: **SPECIAL** | K13: =G13*I13 -> 0
A14: PARSNIP | B14: BX | C14: 8KG | D14: BAUERS | E14: PARBAU | I14: 47 | J14: **NEW LINE - SPECIAL** | K14: =G14*I14 -> 0
A15: POTATO WHITE STAR SEBAGO | B15: BX | C15: 15KG | D15: SPRING LAKES | E15: POTWSSPR | I15: 53 | J15: **SPECIAL** | K15: =G15*I15 -> 0
A16: POTATO SEBAGO | B16: BX | C16: 15KG | D16: WEGNER LOCKYER | E16: POT15WEG POT15LOC | I16: 53 | J16: **SPECIAL** | K16: =G16*I16 -> 0
A17: TOMATO CHERRY 200G | B17: EA | C17: 1PT | D17: SPRING LAKES | E17: TOMCSPR | I17: 3.3 | J17: **SPECIAL** | K17: =G17*I17 -> 0
A18: TURMERIC | B18: KG | C18: PER KG | D18: BELLBIRD NICOLSON | E18: TUMBEL TUMNIC | I18: 23 | J18: **SPECIAL** | K18: =G18*I18 -> 0
E19: GROCERY SPECIALS | K19: .
A20: PRODUCT | B20: SIZE | D20: GROWER | E20: CODE | F20: CUSTOMER COMMENT OR REQUEST | G20: ORDER QTY | H20: PICK QTY | I20: PRICE | J20: Multi Buy Price or Product Info | K20: .
A21: COCONUT MILK LEMONGRASS & GINGER CURRY 400G | B21: BX6 | C21: 400G | D21: BLISSFUL ORGANIC | E21: 01200648 | I21: 22.5 | J21: **SPECIAL** | K21: =G21*I21 -> 0
A22: COCONUT MILK YELLOW CURRY 400G | B22: BX6 | C22: 400G | D22: BLISSFUL ORGANIC | E22: 01200649 | I22: 22.5 | J22: **SPECIAL**
A23: COCONUT MILK GREEN CURRY 400G | B23: BX6 | C23: 400G | D23: BLISSFUL ORGANIC | E23: 01200650 | I23: 22.5 | J23: **SPECIAL** | K23: =G23*I23 -> 0
A24: COCONUT MILK RED CURRY 400G | B24: BX6 | C24: 400G | D24: BLISSFUL ORGANIC | E24: 01200651 | I24: 22.5 | J24: **SPECIAL** | K24: =G24*I24 -> 0
E25: VEGETABLES | K25: =G25*I25 -> 0
A26: PRODUCT | B26: SIZE | D26: GROWER | E26: CODE | F26: CUSTOMER COMMENT OR REQUEST | G26: ORDER QTY | H26: PICK QTY | I26: PRICE | J26: Multi Buy Price or Product Info | K26: .
A27: ARTICHOKE JERUSALEM | B27: KG | C27: PER KG | D27: STORMVIEW | E27: ARTSTO | I27: 20 | K27: =G27*I27 -> 0
A28: ASIAN GREENS BOK CHOY | B28: EA | C28: 1BN | D28: COOLIBAH CREMONA LUNAR | E28: CBOKCOO CBOKCRE CBOKLUN | I28: 3 | J28: 10+ @ $2.80BN | K28: =G28*I28 -> 0
A29: ASIAN GREENS PAK CHOY | B29: EA | C29: 1BN | D29: PENINSULA COOLIBAH LUNAR | E29: CPAKPEN CPAKCRE CPAKLUN CPAKCOO | I29: 3 | J29: 10+ @ $2.80BN | K29: =G29*I29 -> 0
A30: BEANS HAND PICKED | B30: KG | C30: PER KG | D30: MAHAFFEY | E30: BEAMAH | I30: 13.5 | J30: 5KG+ @ $13 KG | K30: =G30*I30 -> 0
A31: BEANS MACHINE PICKED | B31: KG | C31: PER KG | D31: KALFRESH | E31: BEAKAL | I31: 8.8 | J31: 5KG+ @ $8.40 KG | K31: =G31*I31 -> 0
A32: BEETROOT MEDIUM | B32: BG | C32: 10KG | D32: ARAHURA BUSCH | E32: BEEXARA BEEXBUS | I32: 28 | K32: =G32*I32 -> 0
A33: BEETROOT LARGE | B33: BG | C33: 10KG | D33: BAUER | E33: BEELBAU | I33: 30 | K33: =G33*I33 -> 0
A34: BEETROOT PROCESSING | B34: BG | C34: 10KG | D34: BIOFARMS | E34: BEE2BEN | I34: 26 | K34: =G34*I34 -> 0
A35: BEETROOT SMALL | B35: BG | C35: 10KG | D35: BIOFARMS | E35: BEESBEN | I35: 22 | K35: =G35*I35 -> 0
A36: BEETROOT BUNCH | B36: EA | C36: 1BN | D36: COOLIBAH | E36: BEEBCOO | I36: 4.5 | K36: =G36*I36 -> 0
A37: BEETROOT PEELED & COOKED 250G | B37: EA | C37: 1EA | D37: LOVE BEETS | E37: BEELOVE | I37: 4 | J37: 24+ @ $3.80EA | K37: =G37*I37 -> 0
A38: BROCCOLI 8KG | B38: BX | C38: 8KG | D38: MTWHITESTONE BLACK CROW | E38: BROHAR BROBLC | I38: 92 | J38: LIMITED | K38: =G38*I38 -> 0
A39: BROCCOLI BABY PURPLE | B39: BX | C39: 12BN | D39: PENINSULA | E39: BROBPPEN | I39: 50 | K39: =G39*I39 -> 0
A40: CABBAGE GREEN | B40: EA | C40: 1EA | D40: MTWHITESTONE FORDSDALE | E40: CABHAR CABSUT | I40: 5.3 | J40: 12+ @ $5 EA | K40: =G40*I40 -> 0
...

Sheet Office Use Only >>

Sheet B1 B2B
A1: MONDAY 24TH TO WEDNESDAY 26TH AUGUST 2026 | B1: 46255 | C1: 46261 | K1: Order Quantity
A2: CODE | B2: LINK | C2: PRODUCT | D2: PACK | E2: SIZE | F2: GROWER | H2: CERT | I2: PRICE | J2: Multi Buy Price or Product Info | K2: 0
A3: ='Avail List'!E12 -> CAPBLA | B3: FRESH SPECIALS | C3: ='Avail List'!A12 -> CAPSICUM GREEN | D3: ='Avail List'!B12 -> BX | E3: ='Avail List'!C12 -> 5KG | F3: ='Avail List'!D12 -> ISIS RIVER | I3: ='Avail List'!I12 -> 39 | J3: ='Avail List'!J12 -> **SPECIAL** | K3: 1
A4: ='Avail List'!E13 -> CARPBEN | B4: FRESH SPECIALS | C4: ='Avail List'!A13 -> CARROT PURPLE | D4: ='Avail List'!B13 -> BX | E4: ='Avail List'!C13 -> 5KG | F4: ='Avail List'!D13 -> BIOFARMS | I4: ='Avail List'!I13 -> 24 | J4: ='Avail List'!J13 -> **SPECIAL** | K4: 2
A5: ='Avail List'!E14 -> PARBAU | B5: FRESH SPECIALS | C5: ='Avail List'!A14 -> PARSNIP | D5: ='Avail List'!B14 -> BX | E5: ='Avail List'!C14 -> 8KG | F5: ='Avail List'!D14 -> BAUERS | I5: ='Avail List'!I14 -> 47 | J5: ='Avail List'!J14 -> **NEW LINE - SPECIAL** | K5: 3
A6: ='Avail List'!E15 -> POTWSSPR | B6: FRESH SPECIALS | C6: ='Avail List'!A15 -> POTATO WHITE STAR SEBAGO | D6: ='Avail List'!B15 -> BX | E6: ='Avail List'!C15 -> 15KG | F6: ='Avail List'!D15 -> SPRING LAKES | I6: ='Avail List'!I15 -> 53 | J6: ='Avail List'!J15 -> **SPECIAL** | K6: 4
A7: ='Avail List'!E16 -> POT15WEG POT15LOC | B7: FRESH SPECIALS | C7: ='Avail List'!A16 -> POTATO SEBAGO | D7: ='Avail List'!B16 -> BX | E7: ='Avail List'!C16 -> 15KG | F7: ='Avail List'!D16 -> WEGNER LOCKYER | I7: ='Avail List'!I16 -> 53 | J7: ='Avail List'!J16 -> **SPECIAL** | K7: 5
A8: ='Avail List'!E17 -> TOMCSPR | B8: FRESH SPECIALS | C8: ='Avail List'!A17 -> TOMATO CHERRY 200G | D8: ='Avail List'!B17 -> EA | E8: ='Avail List'!C17 -> 1PT | F8: ='Avail List'!D17 -> SPRING LAKES | I8: ='Avail List'!I17 -> 3.3 | J8: ='Avail List'!J17 -> **SPECIAL** | K8: 6
A9: ='Avail List'!E18 -> TUMBEL TUMNIC | B9: FRESH SPECIALS | C9: ='Avail List'!A18 -> TURMERIC | D9: ='Avail List'!B18 -> KG | E9: ='Avail List'!C18 -> PER KG | F9: ='Avail List'!D18 -> BELLBIRD NICOLSON | I9: ='Avail List'!I18 -> 23 | J9: ='Avail List'!J18 -> **SPECIAL** | K9: 7
A10: ='Avail List'!E19 -> GROCERY SPECIALS | B10: FRESH SPECIALS | C10: ='Avail List'!A19 -> 0 | D10: ='Avail List'!B19 -> 0 | E10: ='Avail List'!C19 -> 0 | F10: ='Avail List'!D19 -> 0 | I10: ='Avail List'!I19 -> 0 | J10: ='Avail List'!J19 -> 0 | K10: 8
A11: ='Avail List'!E20 -> CODE | B11: FRESH SPECIALS | C11: ='Avail List'!A20 -> PRODUCT | D11: ='Avail List'!B20 -> SIZE | E11: ='Avail List'!C20 -> 0 | F11: ='Avail List'!D20 -> GROWER | I11: ='Avail List'!I20 -> PRICE | J11: ='Avail List'!J20 -> Multi Buy Price or Product Info | K11: 9
A12: ='Avail List'!E21 -> 01200648 | B12: FRESH SPECIALS | C12: ='Avail List'!A21 -> COCONUT MILK LEMONGRASS & GINGER CURRY 400G | D12: ='Avail List'!B21 -> BX6 | E12: ='Avail List'!C21 -> 400G | F12: ='Avail List'!D21 -> BLISSFUL ORGANIC | I12: ='Avail List'!I21 -> 22.5 | J12: ='Avail List'!J21 -> **SPECIAL** | K12: 10
A13: ='Avail List'!E22 -> 01200649 | B13: FRESH SPECIALS | C13: ='Avail List'!A22 -> COCONUT MILK YELLOW CURRY 400G | D13: ='Avail List'!B22 -> BX6 | E13: ='Avail List'!C22 -> 400G | F13: ='Avail List'!D22 -> BLISSFUL ORGANIC | I13: ='Avail List'!I22 -> 22.5 | J13: ='Avail List'!J22 -> **SPECIAL** | K13: 11
A14: ='Avail List'!E23 -> 01200650 | B14: FRESH SPECIALS | C14: ='Avail List'!A23 -> COCONUT MILK GREEN CURRY 400G | D14: ='Avail List'!B23 -> BX6 | E14: ='Avail List'!C23 -> 400G | F14: ='Avail List'!D23 -> BLISSFUL ORGANIC | I14: ='Avail List'!I23 -> 22.5 | J14: ='Avail List'!J23 -> **SPECIAL** | K14: 12
... A377: ='Avail List'!E386 -> 0 | B377: FRESH SPECIALS | C377: ='Avail List'!A386 -> FOR ANY PREPACK PRODUCE LINES - PLEASE USE OUR PREPACK PRODUCE AVAILABILTY LIST | D377: ='Avail List'!B386 -> 0 | E377: ='Avail List'!C386 -> 0 | F377: ='Avail List'!D386 -> 0 | I377: ='Avail List'!I386 -> 0 | J377: ='Avail List'!J386 -> 0 | K377: 375
A378: WISHLIST 1 | B378: WISHLIST | C378: CHASING ANYTHING EXTRA? TYPE IT IN THE COMMENTS AND IF WE HAVE IT WE WILL SEND IT | I378: 0.01
A379: WISHLIST 2 | B379: WISHLIST | C379: CHASING ANYTHING EXTRA? TYPE IT IN THE COMMENTS AND IF WE HAVE IT WE WILL SEND IT | I379: 0.01
A380: WISHLIST 3 | B380: WISHLIST | C380: CHASING ANYTHING EXTRA? TYPE IT IN THE COMMENTS AND IF WE HAVE IT WE WILL SEND IT | I380: 0.01
A381: WISHLIST 4 | B381: WISHLIST | C381: CHASING ANYTHING EXTRA? TYPE IT IN THE COMMENTS AND IF WE HAVE IT WE WILL SEND IT | I381: 0.01
A382: WISHLIST 5 | B382: WISHLIST | C382: CHASING ANYTHING EXTRA? TYPE IT IN THE COMMENTS AND IF WE HAVE IT WE WILL SEND IT | I382: 0.01
A383: WISHLIST 6 | B383: WISHLIST | C383: CHASING ANYTHING EXTRA? TYPE IT IN THE COMMENTS AND IF WE HAVE IT WE WILL SEND IT | I383: 0.01
